Workbook

Sheet README
A1: Supplementary Table S4
A2: This table contains results of respiration analysis using intact (glycolysis dependent) and permeabilized (glycolysis-independent) HEK293 cell line.
A3: In the last tab we presented calculation of residues used for further respiration determination

Sheet Intact cells
A1: Measurements on intact cells
A3: Temperature [°C] | B3: 1000/K | C3: max respiration | D3: ln(max resp)
A4: 29 | B4: =1000/(273.15+A4) -> 3.3096144 | C4: 16.0798 | D4: =LN(C4) -> 2.7775638
A5: 29 | B5: =1000/(273.15+A5) -> 3.3096144 | C5: 13.2943 | D5: =LN(C5) -> 2.5873354
A6: 29 | B6: =1000/(273.15+A6) -> 3.3096144 | C6: 13.3758 | D6: =LN(C6) -> 2.5934471
A7: 29 | B7: =1000/(273.15+A7) -> 3.3096144 | C7: 17.9037 | D7: =LN(C7) -> 2.8850074
A8: 29 | B8: =1000/(273.15+A8) -> 3.3096144 | C8: 19.4089 | D8: =LN(C8) -> 2.9657317
A9: 31 | B9: =1000/(273.15+A9) -> 3.2878514 | C9: 15.0612 | D9: =LN(C9) -> 2.7121219
A10: 31 | B10: =1000/(273.15+A10) -> 3.2878514 | C10: 15.4507 | D10: =LN(C10) -> 2.7376543
A11: 31 | B11: =1000/(273.15+A11) -> 3.2878514 | C11: 15.6909 | D11: =LN(C11) -> 2.7530809
A12: 31 | B12: =1000/(273.15+A12) -> 3.2878514 | C12: 15.8824 | D12: =LN(C12) -> 2.7652116
A13: 31 | B13: =1000/(273.15+A13) -> 3.2878514 | C13: 21.1472 | D13: =LN(C13) -> 3.0515075
A14: 33 | B14: =1000/(273.15+A14) -> 3.2663727 | C14: 20.2696 | D14: =LN(C14) -> 3.0091222
A15: 33 | B15: =1000/(273.15+A15) -> 3.2663727 | C15: 17.3758 | D15: =LN(C15) -> 2.8550784
... A20: 35 | B20: =1000/(273.15+A20) -> 3.2451728 | C20: 24.6199 | D20: =LN(C20) -> 3.2035551
A21: 35 | B21: =1000/(273.15+A21) -> 3.2451728 | C21: 25.0626 | D21: =LN(C21) -> 3.2213767 | F21: Temperatur | G21: 1000/K | H21: predicted | I21: EXP(predicted) | J21: mean measured | K21: ln(mean measured) | L21: residue
A22: 35 | B22: =1000/(273.15+A22) -> 3.2451728 | C22: 44.8856 | D22: =LN(C22) -> 3.804117 | F22: 29 | G22: 3.3096144 | H22: =EXP(-4.3049*G22+17.057) -> 16.600633 | I22: =-4.3049*G22+17.057 -> 2.8094408 | J22: =AVERAGE(C4:C8) -> 16.0125 | K22: =LN(J22) -> 2.7733697 | L22: =H22-J22 -> 0.58813322 | M22: =I22-K22 -> 0.036071173 | N22: =EXP(M22) -> 1.0367296
A23: 35 | B23: =1000/(273.15+A23) -> 3.2451728 | C23: 23.9838 | D23: =LN(C23) -> 3.1773786 | F23: 31 | G23: 3.2878514 | H23: =EXP(-4.3049*G23+17.057) -> 18.231093 | I23: =-4.3049*G23+17.057 -> 2.9031286 | J23: =AVERAGE(C9:C13) -> 16.64648 | K23: =LN(J23) -> 2.8121988 | L23: =H23-J23 -> 1.5846132 | M23: =I23-K23 -> 0.090929772 | N23: =EXP(M23) -> 1.0951921
A24: 37 | B24: =1000/(273.15+A24) -> 3.2242463 | C24: 24.653 | D24: =LN(C24) -> 3.2048986 | F24: 33 | G24: 3.2663727 | H24: =EXP(-4.3049*G24+17.057) -> 19.997199 | I24: =-4.3049*G24+17.057 -> 2.9955922 | J24: =AVERAGE(C14:C18) -> 19.31158 | K24: =LN(J24) -> 2.9607049 | L24: =H24-J24 -> 0.68561859 | M24: =I24-K24 -> 0.034887277 | N24: =EXP(M24) -> 1.035503
A25: 37 | B25: =1000/(273.15+A25) -> 3.2242463 | C25: 32.7556 | D25: =LN(C25) -> 3.4890739 | F25: 35 | G25: 3.2451728 | H25: =EXP(-4.3049*G25+17.057) -> 21.908082 | I25: =-4.3049*G25+17.057 -> 3.0868556 | J25: =AVERAGE(C19:C23) -> 29.39748 | K25: =LN(J25) -> 3.380909 | L25: =H25-J25 -> -7.4893984 | M25: =I25-K25 -> -0.29405337 | N25: =EXP(M25) -> 0.74523672
A26: 37 | B26: =1000/(273.15+A26) -> 3.2242463 | C26: 54.4866 | D26: =LN(C26) -> 3.9979548 | F26: 37 | G26: 3.2242463 | H26: =EXP(-4.3049*G26+17.057) -> 23.97333 | I26: =-4.3049*G26+17.057 -> 3.176942 | J26: =AVERAGE(C24:C28) -> 37.65986 | K26: =LN(J26) -> 3.6285948 | L26: =H26-J26 -> -13.68653 | M26: =I26-K26 -> -0.45165284 | N26: =EXP(M26) -> 0.63657512
A27: 37 | B27: =1000/(273.15+A27) -> 3.2242463 | C27: 30.5145 | D27: =LN(C27) -> 3.418202 | F27: 38 | G27: 3.21 | H27: =EXP(-4.3049*G27+17.057) -> 25.489612 | I27: =-4.3049*G27+17.057 -> 3.238271 | J27: =AVERAGE(C29:C33) -> 20.54196 | K27: =LN(J27) -> 3.0224696 | L27: =H27-J27 -> 4.9476521 | M27: =I27-K27 -> 0.21580138 | N27: =EXP(M27) -> 1.2408559
A28: 37 | B28: =1000/(273.15+A28) -> 3.2242463 | C28: 45.8896 | D28: =LN(C28) -> 3.8262385 | F28: 39 | G28: 3.2 | H28: =EXP(-4.3049*G28+17.057) -> 26.610876 | I28: =-4.3049*G28+17.057 -> 3.28132 | J28: =AVERAGE(C34:C38) -> 20.36988 | K28: =LN(J28) -> 3.0140573 | L28: =H28-J28 -> 6.2409959 | M28: =I28-K28 -> 0.26726266 | N28: =EXP(M28) -> 1.3063835
A29: 38 | B29: =1000/(273.15+A29) -> 3.213884 | C29: 20.7318 | D29: =LN(C29) -> 3.0316688 | F29: 40 | G29: 3.19 | H29: =EXP(-4.3049*G29+17.057) -> 27.781463 | I29: =-4.3049*G29+17.057 -> 3.324369 | J29: =AVERAGE(C39:C43) -> 23.36316 | K29: =LN(J29) -> 3.1511604 | L29: =H29-J29 -> 4.418303 | M29: =I29-K29 -> 0.17320858 | N29: =EXP(M29) -> 1.1891141
A30: 38 | B30: =1000/(273.15+A30) -> 3.213884 | C30: 21.0688 | D30: =LN(C30) -> 3.0477933 | F30: 41 | G30: 3.18 | H30: =EXP(-4.3049*G30+17.057) -> 29.003543 | I30: =-4.3049*G30+17.057 -> 3.367418 | J30: =AVERAGE(C44:C48) -> 26.6382 | K30: =LN(J30) -> 3.2823463 | L30: =H30-J30 -> 2.3653431 | M30: =I30-K30 -> 0.085071724 | N30: =EXP(M30) -> 1.0887952
A31: 38 | B31: =1000/(273.15+A31) -> 3.213884 | C31: 19.5649 | D31: =LN(C31) -> 2.9737371 | F31: 42 | G31: 3.17 | H31: =EXP(-4.3049*G31+17.057) -> 30.279381 | I31: =-4.3049*G31+17.057 -> 3.410467 | J31: =AVERAGE(C49:C53) -> 27.66832 | K31: =LN(J31) -> 3.3202881 | L31: =H31-J31 -> 2.6110614 | M31: =I31-K31 -> 0.090178924 | N31: =EXP(M31) -> 1.0943701
A32: 38 | B32: =1000/(273.15+A32) -> 3.213884 | C32: 18.8869 | D32: =LN(C32) -> 2.9384686 | F32: 43 | G32: 3.16 | H32: =EXP(-4.3049*G32+17.057) -> 31.611343 | I32: =-4.3049*G32+17.057 -> 3.453516 | J32: =AVERAGE(C54:C58) -> 25.65698 | K32: =LN(J32) -> 3.2448157 | L32: =H32-J32 -> 5.9543626 | M32: =I32-K32 -> 0.20870034 | N32: =EXP(M32) -> 1.2320757
A33: 38 | B33: =1000/(273.15+A33) -> 3.213884 | C33: 22.4574 | D33: =LN(C33) -> 3.1116202 | F33: 44 | G33: 3.15 | H33: =EXP(-4.3049*G33+17.057) -> 33.001896 | I33: =-4.3049*G33+17.057 -> 3.496565 | J33: =AVERAGE(C59:C63) -> 24.17334 | K33: =LN(J33) -> 3.1852504 | L33: =H33-J33 -> 8.8285555 | M33: =I33-K33 -> 0.31131463 | N33: =EXP(M33) -> 1.3652187
A34: 39 | B34: =1000/(273.15+A34) -> 3.203588 | C34: 24.6881 | D34: =LN(C34) -> 3.2063213 | F34: 45 | G34: 3.14 | H34: =EXP(-4.3049*G34+17.057) -> 34.453618 | I34: =-4.3049*G34+17.057 -> 3.539614 | J34: =AVERAGE(C64:C68) -> 22.72874 | K34: =LN(J34) -> 3.1236302 | L34: =H34-J34 -> 11.724878 | M34: =I34-K34 -> 0.4159838 | N34: =EXP(M34) -> 1.5158613
A35: 39 | B35: =1000/(273.15+A35) -> 3.203588 | C35: 18.99 | D35: =LN(C35) -> 2.9439125 | F35: 46 | G35: 3.13 | H35: =EXP(-4.3049*G35+17.057) -> 35.969199 | I35: =-4.3049*G35+17.057 -> 3.582663 | J35: =AVERAGE(C69:C73) -> 9.83214 | K35: =LN(J35) -> 2.2856566 | L35: =H35-J35 -> 26.137059 | M35: =I35-K35 -> 1.2970064 | N35: =EXP(M35) -> 3.6583286
A36: 39 | B36: =1000/(273.15+A36) -> 3.203588 | C36: 19.938 | D36: =LN(C36) -> 2.9926275 | F36: 47 | G36: 3.12 | H36: =EXP(-4.3049*G36+17.057) -> 37.55145 | I36: =-4.3049*G36+17.057 -> 3.625712 | J36: =AVERAGE(C74:C78) -> 4.7708 | K36: =LN(J36) -> 1.562514 | L36: =H36-J36 -> 32.78065 | M36: =I36-K36 -> 2.063198 | N36: =EXP(M36) -> 7.8711013
A37: 39 | B37: =1000/(273.15+A37) -> 3.203588 | C37: 15.8267 | D37: =LN(C37) -> 2.7616984
A38: 39 | B38: =1000/(273.15+A38) -> 3.203588 | C38: 22.4066 | D38: =LN(C38) -> 3.1093556
A39: 40 | B39: =1000/(273.15+A39) -> 3.1933578 | C39: 22.1884 | D39: =LN(C39) -> 3.0995696
A40: 40 | B40: =1000/(273.15+A40) -> 3.1933578 | C40: 18.4342 | D40: =LN(C40) -> 2.9142076
A41: 40 | B41: =1000/(273.15+A41) -> 3.1933578 | C41: 28.3976 | D41: =LN(C41) -> 3.3463046 | H41: =H38-J38 -> 0 | J41: =EXP(H41) -> 1
A42: 40 | B42: =1000/(273.15+A42) -> 3.1933578 | C42: 23.0113 | D42: =LN(C42) -> 3.1359854
A43: 40 | B43: =1000/(273.15+A43) -> 3.1933578 | C43: 24.7843 | D43: =LN(C43) -> 3.2102104
A44: 41 | B44: =1000/(273.15+A44) -> 3.1831927 | C44: 23.6497 | D44: =LN(C44) -> 3.1633504
A45: 41 | B45: =1000/(273.15+A45) -> 3.1831927 | C45: 21.7116 | D45: =LN(C45) -> 3.0778467
...

Sheet Permeabilized cells
A1: Measurements on permeabilized cells
A3: Temperature [°C] | B3: 1000/K | C3: max respiration | D3: ln(max respiration)
A4: 29 | B4: =1000/(273.15+A4) -> 3.3096144 | C4: 26.5858 | D4: =LN(C4) -> 3.2803772
A5: 29 | B5: =1000/(273.15+A5) -> 3.3096144 | C5: 24.0549 | D5: =LN(C5) -> 3.1803387
A6: 29 | B6: =1000/(273.15+A6) -> 3.3096144 | C6: 26.963 | D6: =LN(C6) -> 3.2944656
A7: 29 | B7: =1000/(273.15+A7) -> 3.3096144 | C7: 33.3321 | D7: =LN(C7) -> 3.5065209
A8: 29 | B8: =1000/(273.15+A8) -> 3.3096144 | C8: 35.1036 | D8: =LN(C8) -> 3.5583037
A9: 31 | B9: =1000/(273.15+A9) -> 3.2878514 | C9: 31.0487 | D9: =LN(C9) -> 3.4355569
A10: 31 | B10: =1000/(273.15+A10) -> 3.2878514 | C10: 24.5998 | D10: =LN(C10) -> 3.2027383
A11: 31 | B11: =1000/(273.15+A11) -> 3.2878514 | C11: 23.819 | D11: =LN(C11) -> 3.1704836
A12: 31 | B12: =1000/(273.15+A12) -> 3.2878514 | C12: 26.5827 | D12: =LN(C12) -> 3.2802606
A13: 31 | B13: =1000/(273.15+A13) -> 3.2878514 | C13: 39.5049 | D13: =LN(C13) -> 3.6764247
A14: 33 | B14: =1000/(273.15+A14) -> 3.2663727 | C14: 39.1456 | D14: =LN(C14) -> 3.667288
A15: 33 | B15: =1000/(273.15+A15) -> 3.2663727 | C15: 33.1847 | D15: =LN(C15) -> 3.5020889
... A36: 39 | B36: =1000/(273.15+A36) -> 3.203588 | C36: 25.0991 | D36: =LN(C36) -> 3.222832
A37: 39 | B37: =1000/(273.15+A37) -> 3.203588 | C37: 14.4992 | D37: =LN(C37) -> 2.6740935 | F37: Temperature [°C] | G37: 1000/K | H37: predicted | I37: mean measured | J37: Residue
A38: 39 | B38: =1000/(273.15+A38) -> 3.203588 | C38: 25.295 | D38: =LN(C38) -> 3.2306067 | F38: 29 | G38: 3.3096144 | H38: =EXP(-1.7088*G38+9.0415) -> 29.548437 | I38: =AVERAGE(C4:C8) -> 29.20788 | J38: =H38-I38 -> 0.34055739
A39: 40 | B39: =1000/(273.15+A39) -> 3.1933578 | C39: 34.7411 | D39: =LN(C39) -> 3.5479234 | F39: 31 | G39: 3.2878514 | H39: =EXP(-1.7088*G39+9.0415) -> 30.667993 | I39: =AVERAGE(C9:C13) -> 29.11102 | J39: =H39-I39 -> 1.5569733
A40: 40 | B40: =1000/(273.15+A40) -> 3.1933578 | C40: 37.8304 | D40: =LN(C40) -> 3.633113 | F40: 33 | G40: 3.2663727 | H40: =EXP(-1.7088*G40+9.0415) -> 31.814506 | I40: =AVERAGE(C14:C18) -> 29.94388 | J40: =H40-I40 -> 1.8706258
A41: 40 | B41: =1000/(273.15+A41) -> 3.1933578 | C41: 26.0917 | D41: =LN(C41) -> 3.2616173 | F41: 35 | G41: 3.2451728 | H41: =EXP(-1.7088*G41+9.0415) -> 32.98816 | I41: =AVERAGE(C19:C23) -> 42.34486 | J41: =H41-I41 -> -9.3567
A42: 40 | B42: =1000/(273.15+A42) -> 3.1933578 | C42: 28.1414 | D42: =LN(C42) -> 3.3372418 | F42: 37 | G42: 3.2242463 | H42: =EXP(-1.7088*G42+9.0415) -> 34.189134 | I42: =AVERAGE(C24:C28) -> 56.8437 | J42: =H42-I42 -> -22.654566
A43: 40 | B43: =1000/(273.15+A43) -> 3.1933578 | C43: 40.4833 | D43: =LN(C43) -> 3.7008895 | F43: 38 | G43: 3.21 | H43: =EXP(-1.7088*G43+9.0415) -> 35.031652 | I43: =AVERAGE(C29:C33) -> 29.70272 | J43: =H43-I43 -> 5.3289322
A44: 41 | B44: =1000/(273.15+A44) -> 3.1831927 | C44: 36.959 | D44: =LN(C44) -> 3.6098092 | F44: 39 | G44: 3.2 | H44: =EXP(-1.7088*G44+9.0415) -> 35.635417 | I44: =AVERAGE(C34:C38) -> 30.35492 | J44: =H44-I44 -> 5.2804969
A45: 41 | B45: =1000/(273.15+A45) -> 3.1831927 | C45: 21.6767 | D45: =LN(C45) -> 3.076238 | F45: 40 | G45: 3.19 | H45: =EXP(-1.7088*G45+9.0415) -> 36.249587 | I45: =AVERAGE(C39:C43) -> 33.45758 | J45: =H45-I45 -> 2.7920074
A46: 41 | B46: =1000/(273.15+A46) -> 3.1831927 | C46: 37.2013 | D46: =LN(C46) -> 3.6163437 | F46: 41 | G46: 3.18 | H46: =EXP(-1.7088*G46+9.0415) -> 36.874343 | I46: =AVERAGE(C44:C48) -> 33.86642 | J46: =H46-I46 -> 3.0079231
A47: 41 | B47: =1000/(273.15+A47) -> 3.1831927 | C47: 38.2675 | D47: =LN(C47) -> 3.644601 | F47: 42 | G47: 3.17 | H47: =EXP(-1.7088*G47+9.0415) -> 37.509866 | I47: =AVERAGE(C49:C53) -> 38.10174 | J47: =H47-I47 -> -0.59187369
A48: 41 | B48: =1000/(273.15+A48) -> 3.1831927 | C48: 35.2276 | D48: =LN(C48) -> 3.5618299 | F48: 43 | G48: 3.16 | H48: =EXP(-1.7088*G48+9.0415) -> 38.156343 | I48: =AVERAGE(C54:C58) -> 38.36384 | J48: =H48-I48 -> -0.20749733
A49: 42 | B49: =1000/(273.15+A49) -> 3.1730922 | C49: 43.9061 | D49: =LN(C49) -> 3.7820533 | F49: 44 | G49: 3.15 | H49: =EXP(-1.7088*G49+9.0415) -> 38.813961 | I49: =AVERAGE(C59:C63) -> 32.73104 | J49: =H49-I49 -> 6.0829209
A50: 42 | B50: =1000/(273.15+A50) -> 3.1730922 | C50: 42.0113 | D50: =LN(C50) -> 3.7379386 | F50: 45 | G50: 3.14 | H50: =EXP(-1.7088*G50+9.0415) -> 39.482913 | I50: =AVERAGE(C64:C68) -> 40.16878 | J50: =H50-I50 -> -0.68586684
A51: 42 | B51: =1000/(273.15+A51) -> 3.1730922 | C51: 15.6215 | D51: =LN(C51) -> 2.7486482 | F51: 46 | G51: 3.13 | H51: =EXP(-1.7088*G51+9.0415) -> 40.163395 | I51: =AVERAGE(C69:C73) -> 30.05108 | J51: =H51-I51 -> 10.112315
A52: 42 | B52: =1000/(273.15+A52) -> 3.1730922 | C52: 46.1672 | D52: =LN(C52) -> 3.8322696 | F52: 47 | G52: 3.12 | H52: =EXP(-1.7088*G52+9.0415) -> 40.855604 | I52: =AVERAGE(C74:C78) -> 12.98614 | J52: =H52-I52 -> 27.869464
A53: 42 | B53: =1000/(273.15+A53) -> 3.1730922 | C53: 42.8026 | D53: =LN(C53) -> 3.7565988
A54: 43 | B54: =1000/(273.15+A54) -> 3.1630555 | C54: 39.1178 | D54: =LN(C54) -> 3.6665776
A55: 43 | B55: =1000/(273.15+A55) -> 3.1630555 | C55: 49.5586 | D55: =LN(C55) -> 3.9031558
A56: 43 | B56: =1000/(273.15+A56) -> 3.1630555 | C56: 38.1442 | D56: =LN(C56) -> 3.6413737
A57: 43 | B57: =1000/(273.15+A57) -> 3.1630555 | C57: 39.7507 | D57: =LN(C57) -> 3.6826275
A58: 43 | B58: =1000/(273.15+A58) -> 3.1630555 | C58: 25.2479 | D58: =LN(C58) -> 3.228743
A59: 44 | B59: =1000/(273.15+A59) -> 3.1530821 | C59: 14.0231 | D59: =LN(C59) -> 2.640706
A60: 44 | B60: =1000/(273.15+A60) -> 3.1530821 | C60: 16.4569 | D60: =LN(C60) -> 2.8007448
A61: 44 | B61: =1000/(273.15+A61) -> 3.1530821 | C61: 31.533 | D61: =LN(C61) -> 3.4510346
...

Sheet Calculation of residues
A1: Calculation of residues
B3: Intact cells | J3: Permeabilized cells
A4: Temperature [°C] | B4: ln(max resp intact) | C4: predicted | D4: ln (predicted) | E4: predicted -measured | F4: measured-predicted | H4: Temperature [°C] | I4: max resp permeabilized | J4: ln(max resp) | K4: predicted | L4: ln(predicted) | M4: predicted - measured | N4: measured-predicted
A5: 29 | B5: ='Intact cells'!$D4 -> 2.7775638 | C5: 16.600633 | D5: =LN(C5) -> 2.8094408 | E5: =D5-B5 -> 0.031877015 | F5: =B5-D5 -> -0.031877015 | H5: 29 | I5: 26.5858 | J5: =LN(I5) -> 3.2803772 | K5: 29.548437 | L5: =LN(K5) -> 3.3860309 | M5: =L5-J5 -> 0.10565362 | N5: =J5-L5 -> -0.10565362
A6: 29 | B6: ='Intact cells'!$D5 -> 2.5873354 | C6: 16.600633 | D6: =LN(C6) -> 2.8094408 | E6: =D6-B6 -> 0.22210547 | F6: =B6-D6 -> -0.22210547 | H6: 29 | I6: 24.0549 | J6: =LN(I6) -> 3.1803387 | K6: 29.548437 | L6: =LN(K6) -> 3.3860309 | M6: =L6-J6 -> 0.20569214 | N6: =J6-L6 -> -0.20569214
A7: 29 | B7: ='Intact cells'!$D6 -> 2.5934471 | C7: 16.600633 | D7: =LN(C7) -> 2.8094408 | E7: =D7-B7 -> 0.21599374 | F7: =B7-D7 -> -0.21599374 | H7: 29 | I7: 26.963 | J7: =LN(I7) -> 3.2944656 | K7: 29.548437 | L7: =LN(K7) -> 3.3860309 | M7: =L7-J7 -> 0.091565306 | N7: =J7-L7 -> -0.091565306
A8: 29 | B8: ='Intact cells'!$D7 -> 2.8850074 | C8: 16.600633 | D8: =LN(C8) -> 2.8094408 | E8: =D8-B8 -> -0.075566555 | F8: =B8-D8 -> 0.075566555 | H8: 29 | I8: 33.3321 | J8: =LN(I8) -> 3.5065209 | K8: 29.548437 | L8: =LN(K8) -> 3.3860309 | M8: =L8-J8 -> -0.12049003 | N8: =J8-L8 -> 0.12049003
A9: 29 | B9: ='Intact cells'!$D8 -> 2.9657317 | C9: 16.600633 | D9: =LN(C9) -> 2.8094408 | E9: =D9-B9 -> -0.15629088 | F9: =B9-D9 -> 0.15629088 | H9: 29 | I9: 35.1036 | J9: =LN(I9) -> 3.5583037 | K9: 29.548437 | L9: =LN(K9) -> 3.3860309 | M9: =L9-J9 -> -0.17227283 | N9: =J9-L9 -> 0.17227283
A10: 31 | B10: ='Intact cells'!$D9 -> 2.7121219 | C10: 18.231093 | D10: =LN(C10) -> 2.9031286 | E10: =D10-B10 -> 0.19100665 | F10: =B10-D10 -> -0.19100665 | H10: 31 | I10: 31.0487 | J10: =LN(I10) -> 3.4355569 | K10: 30.667993 | L10: =LN(K10) -> 3.4232195 | M10: =L10-J10 -> -0.012337393 | N10: =J10-L10 -> 0.012337393
A11: 31 | B11: ='Intact cells'!$D10 -> 2.7376543 | C11: 18.231093 | D11: =LN(C11) -> 2.9031286 | E11: =D11-B11 -> 0.16547425 | F11: =B11-D11 -> -0.16547425 | H11: 31 | I11: 24.5998 | J11: =LN(I11) -> 3.2027383 | K11: 30.667993 | L11: =LN(K11) -> 3.4232195 | M11: =L11-J11 -> 0.22048123 | N11: =J11-L11 -> -0.22048123
A12: 31 | B12: ='Intact cells'!$D11 -> 2.7530809 | C12: 18.231093 | D12: =LN(C12) -> 2.9031286 | E12: =D12-B12 -> 0.15004763 | F12: =B12-D12 -> -0.15004763 | H12: 31 | I12: 23.819 | J12: =LN(I12) -> 3.1704836 | K12: 30.667993 | L12: =LN(K12) -> 3.4232195 | M12: =L12-J12 -> 0.25273596 | N12: =J12-L12 -> -0.25273596
A13: 31 | B13: ='Intact cells'!$D12 -> 2.7652116 | C13: 18.231093 | D13: =LN(C13) -> 2.9031286 | E13: =D13-B13 -> 0.13791698 | F13: =B13-D13 -> -0.13791698 | H13: 31 | I13: 26.5827 | J13: =LN(I13) -> 3.2802606 | K13: 30.667993 | L13: =LN(K13) -> 3.4232195 | M13: =L13-J13 -> 0.14295892 | N13: =J13-L13 -> -0.14295892
A14: 31 | B14: ='Intact cells'!$D13 -> 3.0515075 | C14: 18.231093 | D14: =LN(C14) -> 2.9031286 | E14: =D14-B14 -> -0.14837895 | F14: =B14-D14 -> 0.14837895 | H14: 31 | I14: 39.5049 | J14: =LN(I14) -> 3.6764247 | K14: 30.667993 | L14: =LN(K14) -> 3.4232195 | M14: =L14-J14 -> -0.25320517 | N14: =J14-L14 -> 0.25320517
A15: 33 | B15: ='Intact cells'!$D14 -> 3.0091222 | C15: 19.997199 | D15: =LN(C15) -> 2.9955922 | E15: =D15-B15 -> -0.013530033 | F15: =B15-D15 -> 0.013530033 | H15: 33 | I15: 39.1456 | J15: =LN(I15) -> 3.667288 | K15: 31.814506 | L15: =LN(K15) -> 3.4599223 | M15: =L15-J15 -> -0.20736569 | N15: =J15-L15 -> 0.20736569
A16: 33 | B16: ='Intact cells'!$D15 -> 2.8550784 | C16: 19.997199 | D16: =LN(C16) -> 2.9955922 | E16: =D16-B16 -> 0.14051376 | F16: =B16-D16 -> -0.14051376 | H16: 33 | I16: 33.1847 | J16: =LN(I16) -> 3.5020889 | K16: 31.814506 | L16: =LN(K16) -> 3.4599223 | M16: =L16-J16 -> -0.042166584 | N16: =J16-L16 -> 0.042166584
... A79: 47 | B79: ='Intact cells'!$D78 -> 1.5819023 | C79: 37.55145 | D79: =LN(C79) -> 3.625712 | E79: =D79-B79 -> 2.0438097 | F79: =B79-D79 -> -2.0438097 | H79: 47 | I79: 10.8723 | J79: =LN(I79) -> 2.3862183 | K79: 40.855604 | L79: =LN(K79) -> 3.710044 | M79: =L79-J79 -> 1.3238257 | N79: =J79-L79 -> -1.3238257
